Workbook

Sheet Summary
A1: Summary statistics
A3: Scope of this dataset
A4: Number of approaches: | B4: =COUNTA(Approaches!C:C)-1
A5: Number of instruments: | B5: =COUNTA('Instruments overview'!A:A)-2
A6: Sectors covered: | B6: Energy, transport, buildings, industry, AFOLU, waste
A9: Category | B9: Group | C9: Number of Approaches | D9: Number of Instruments | H9: Category | I9: Number of Approaches | J9: Number of Instruments
A10: Economic instruments | B10: Trading scheme | C10: =COUNTIF(Approaches!B:B, "Trading scheme") | D10: =COUNTIF('Instruments overview'!J:J, "Trading scheme") | H10: Economic instruments | I10: =COUNTIF(Approaches!A:A, "Economic") | J10: =COUNTIF('Instruments overview'!I:I, "Economic instruments")
B11: Subsidy | C11: =COUNTIF(Approaches!B:B, "Subsidy") | D11: =COUNTIF('Instruments overview'!J:J, "Subsidy") | H11: Regulatory instruments | I11: =COUNTIF(Approaches!A:A, "Regulatory") | J11: =COUNTIF('Instruments overview'!I:I, "Regulatory instruments")
B12: Tax | C12: =COUNTIF(Approaches!B:B, "Tax") | D12: =COUNTIF('Instruments overview'!J:J, "Tax") | H12: Government I&C | I12: =COUNTIF(Approaches!A:A, "Government investment and consumption") | J12: =COUNTIF('Instruments overview'!I:I, "Government I&C")
B13: Administered price | C13: =COUNTIF(Approaches!B:B, "Administered price") | D13: =COUNTIF('Instruments overview'!J:J, "Administered price") | H13: Information instruments | I13: =COUNTIF(Approaches!A:A, "Information") | J13: =COUNTIF('Instruments overview'!I:I, "Information instruments")
A14: Regulatory instruments | B14: Technology standard | C14: =COUNTIF(Approaches!B:B, "Technology standard") | D14: =COUNTIF('Instruments overview'!J:J, "Technology standard") | H14: Voluntary approaches | I14: =COUNTIF(Approaches!A:A, "Voluntary") | J14: =COUNTIF('Instruments overview'!I:I, "Voluntary approaches")
B15: Performance standard | C15: =COUNTIF(Approaches!B:B, "Performance standard") | D15: =COUNTIF('Instruments overview'!J:J, "Performance standard")
B16: Framework regulation | C16: =COUNTIF(Approaches!B:B, "Framework regulation") | D16: =COUNTIF('Instruments overview'!J:J, "Framework regulation")
A17: Government I&C | B17: Public procurement | C17: =COUNTIF(Approaches!B:B, "Public procurement") | D17: =COUNTIF('Instruments overview'!J:J, "Public procurement") | H17: Emission Sector | I17: Number of Approaches | J17: Number of Instruments
B18: Public investment | C18: =COUNTIF(Approaches!B:B, "Public investment") | D18: =COUNTIF('Instruments overview'!J:J, "Public investment") | H18: Energy | I18: =SUMPRODUCT((ISNUMBER(SEARCH("Energy",Approaches!F:F)))*1) | J18: =COUNTIF('Instruments overview'!K:K, "*Energy*")
B19: Public appraisal rule | C19: =COUNTIF(Approaches!B:B, "Public appraisal rules") | D19: =COUNTIF('Instruments overview'!J:J, "Public appraisal rules") | H19: Industry | I19: =SUMPRODUCT((ISNUMBER(SEARCH("Industry",Approaches!F:F)))*1) | J19: =COUNTIF('Instruments overview'!K:K, "*Industry*")
A20: Information instruments | B20: Label | C20: =COUNTIF(Approaches!B:B, "Comparative energy efficiency label") | D20: =COUNTIF('Instruments overview'!J:J, "Comparative energy efficiency label") | H20: Buildings | I20: =SUMPRODUCT((ISNUMBER(SEARCH("Buildings",Approaches!F:F)))*1) | J20: =COUNTIF('Instruments overview'!K:K, "*Buildings*")
B21: Reporting requirement | C21: =COUNTIF(Approaches!B:B, "Reporting requirements") | D21: =COUNTIF('Instruments overview'!J:J, "Reporting requirements") | H21: Transport | I21: =SUMPRODUCT((ISNUMBER(SEARCH("Transport",Approaches!F:F)))*1) | J21: =COUNTIF('Instruments overview'!K:K, "*Transport*")
B22: Capacity building and public awareness | C22: =COUNTIF(Approaches!B:B, "Capacity building and public awareness") | D22: =COUNTIF('Instruments overview'!J:J, "Capacity building and public awareness") | H22: AFOLU | I22: =SUMPRODUCT((ISNUMBER(SEARCH("AFOLU",Approaches!F:F)))*1) | J22: =COUNTIF('Instruments overview'!K:K, "*AFOLU*")
A23: Voluntary approaches | B23: Voluntary information instrument | C23: =COUNTIF(Approaches!B:B, "Voluntary information instrument") | D23: =COUNTIF('Instruments overview'!J:J, "Voluntary information instrument") | H23: Waste | I23: =SUMPRODUCT((ISNUMBER(SEARCH("Waste",Approaches!F:F)))*1) | J23: =COUNTIF('Instruments overview'!K:K, "*Waste*")
B24: Voluntary target | C24: =COUNTIF(Approaches!B:B, "Voluntary target") | D24: =COUNTIF('Instruments overview'!J:J, "Voluntary target") | H24: Cross-sectoral | I24: =SUMPRODUCT((ISNUMBER(SEARCH("Cross-sectoral",Approaches!F:F)))*1) | J24: =COUNTIF('Instruments overview'!K:K, "*Cross-sectoral*")
B25: Voluntary trading system | C25: =COUNTIF(Approaches!B:B, "Voluntary trading system") | D25: =COUNTIF('Instruments overview'!J:J, "Voluntary trading system")
A27: Note: The sum of numbers for "category" and "group" equals the total number of approaches/instruments, since each approach/instrument only belongs to one category/group. The sum of numbers in the other tables are larger than the total number of approaches/instruments since some approaches/instruments belong to more than one classification.
H30: Mitigation relevance | I30: Number of Approaches | J30: Number of Instruments
H31: Direct | I31: =SUMPRODUCT((ISNUMBER(SEARCH("Direct",Approaches!G:G)))*1) | J31: =COUNTIF('Instruments overview'!H:H, "Direct")
H32: Indirect | I32: =SUMPRODUCT((ISNUMBER(SEARCH("Indirect",Approaches!G:G)))*1) | J32: =COUNTIF('Instruments overview'!H:H, "Indirect")
I35: Economic instruments | J35: Regulatory instruments | K35: Government I&C | L35: Information instruments | M35: Voluntary approaches | N35: Total number of approaches
H36: Energy | I36: =COUNTIFS(Approaches!F:F, "*Energy*", Approaches!A:A, "Economic") | J36: =COUNTIFS(Approaches!F:F, "*Energy*", Approaches!A:A, "Regulatory") | K36: =COUNTIFS(Approaches!F:F, "*Energy*", Approaches!A:A, "Government investment and consumption") | L36: =COUNTIFS(Approaches!F:F, "*Energy*", Approaches!A:A, "Information") | M36: =COUNTIFS(Approaches!F:F, "*Energy*", Approaches!A:A, "Voluntary") | N36: =SUM(I36:M36)
H37: Industry | I37: =COUNTIFS(Approaches!F:F, "*Industry*", Approaches!A:A, "Economic") | J37: =COUNTIFS(Approaches!F:F, "*Industry*", Approaches!A:A, "Regulatory") | K37: =COUNTIFS(Approaches!F:F, "*Industry*", Approaches!A:A, "Government investment and consumption") | L37: =COUNTIFS(Approaches!F:F, "*Industry*", Approaches!A:A, "Information") | M37: =COUNTIFS(Approaches!F:F, "*Industry*", Approaches!A:A, "Voluntary") | N37: =SUM(I37:M37)
H38: Buildings | I38: =COUNTIFS(Approaches!F:F, "*Buildings*", Approaches!A:A, "Economic") | J38: =COUNTIFS(Approaches!F:F, "*Buildings*", Approaches!A:A, "Regulatory") | K38: =COUNTIFS(Approaches!F:F, "*Buildings*", Approaches!A:A, "Government investment and consumption") | L38: =COUNTIFS(Approaches!F:F, "*Buildings*", Approaches!A:A, "Information") | M38: =COUNTIFS(Approaches!F:F, "*Buildings*", Approaches!A:A, "Voluntary") | N38: =SUM(I38:M38)
H39: Transport | I39: =COUNTIFS(Approaches!F:F, "*Transport*", Approaches!A:A, "Economic") | J39: =COUNTIFS(Approaches!F:F, "*Transport*", Approaches!A:A, "Regulatory") | K39: =COUNTIFS(Approaches!F:F, "*Transport*", Approaches!A:A, "Government investment and consumption") | L39: =COUNTIFS(Approaches!F:F, "*Transport*", Approaches!A:A, "Information") | M39: =COUNTIFS(Approaches!F:F, "*Transport*", Approaches!A:A, "Voluntary") | N39: =SUM(I39:M39)
H40: AFOLU | I40: =COUNTIFS(Approaches!F:F, "*AFOLU*", Approaches!A:A, "Economic") | J40: =COUNTIFS(Approaches!F:F, "*AFOLU*", Approaches!A:A, "Regulatory") | K40: =COUNTIFS(Approaches!F:F, "*AFOLU*", Approaches!A:A, "Government investment and consumption") | L40: =COUNTIFS(Approaches!F:F, "*AFOLU*", Approaches!A:A, "Information") | M40: =COUNTIFS(Approaches!F:F, "*AFOLU*", Approaches!A:A, "Voluntary") | N40: =SUM(I40:M40)
H41: Waste | I41: =COUNTIFS(Approaches!F:F, "*Waste*", Approaches!A:A, "Economic") | J41: =COUNTIFS(Approaches!F:F, "*Waste*", Approaches!A:A, "Regulatory") | K41: =COUNTIFS(Approaches!F:F, "*Waste*", Approaches!A:A, "Government investment and consumption") | L41: =COUNTIFS(Approaches!F:F, "*Waste*", Approaches!A:A, "Information") | M41: =COUNTIFS(Approaches!F:F, "*Waste*", Approaches!A:A, "Voluntary") | N41: =SUM(I41:M41)
H42: Cross-sectoral | I42: =COUNTIFS(Approaches!F:F, "*Cross-sectoral*", Approaches!A:A, "Economic") | J42: =COUNTIFS(Approaches!F:F, "*Cross-sectoral*", Approaches!A:A, "Regulatory") | K42: =COUNTIFS(Approaches!F:F, "*Cross-sectoral*", Approaches!A:A, "Government investment and consumption") | L42: =COUNTIFS(Approaches!F:F, "*Cross-sectoral*", Approaches!A:A, "Information") | M42: =COUNTIFS(Approaches!F:F, "*Cross-sectoral*", Approaches!A:A, "Voluntary") | N42: =SUM(I42:M42)

Sheet Economic instruments
A1: Identification | C1: Instrument typology | G1: Policy description | M1: Administrative information | V1: Policy regulatory base and intensity | AK1: Instrument-specific attributes | BD1: GHG emission base | BF1: Classification & Indicators | BJ1: References to legislation
A2: Policy Instrument ID | B2: Instrument / subscheme | C2: Group | D2: Approach | E2: Emission sector | F2: Sub-sector | G2: Domestic instrument name | H2: English instrument name | I2: Policy Package | J2: Description | K2: Objective | L2: Mitigation relevance | M2: Jurisdiction level | N2: Jurisdiction name | O2: Adoption date | P2: Start date | Q2: End date | R2: Last revisions | S2: Last revisions (Details) | T2: Status | U2: Administrating authorities | V2: Asset | W2: Asset (Status) | X2: Asset (Details) | Y2: Asset (Other) | Z2: Asset (Cut-off range) | AA2: Agent | AB2: Agent (Detail) | AC2: Activity | AD2: Activity (Details) | AE2: Intensity (Value) | AF2: Intensity (Unit) | AG2: Intensity (Details) | AH2: Requirement specification | AI2: Compliance calculation methodology I | AJ2: Compliance calculation methodology II | AK2: Tax and Tax Incentive: annual revenue | AL2: Tax and Tax Incentive: earmarked revenue | AM2: Tax and Tax Incentive: annual revenue forgone | AN2: Subsidy: annual budget/ expenditure | AO2: Subsidy: Limit | AP2: Subsidy: Floor or ceiling | AQ2: Subsidy: distribution mechanism | AR2: Subsidy: Support duration | AS2: Subsidy: Enforcement Mechanism | AT2: Trading System: Type | AU2: Trading System: cap | AV2: Trading System: allowance mechanism | AW2: Trading System: Free Allowance | AX2: Trading System: Offset use allowed | AY2: Trading System: Linkages | AZ2: Trading System: market stabilisation mechanism | BA2: Trading System: revenue (annual) | BB2: Trading System: Volume | BC2: Trading System: penalties for non-compliance | BD2: GHG emission coverage (absolute) | BE2: GHG emission coverage (% domestic emissions) | BF2: Economic sector | BG2: GHGs affected | BH2: Mitigation effects | BI2: Mitigation co-benefits | BJ2: Legal statute | BK2: Legal document | BL2: Other weblinks

Sheet Instruments overview
A1: Instrument ID | B1: Approach | C1: English instrument name | D1: Domestic instrument name | E1: Status | F1: Start time | G1: End time | H1: Mitigation relevance | I1: Category | J1: Group | K1: Emission sector | L1: Sub-sector

Sheet Regulatory instruments
A1: Identification | C1: Instrument typology | G1: Policy description | M1: Administrative information | V1: Policy regulatory base and intensity | AK1: Instrument-specific attributes | AQ1: GHG emission base | AS1: Classification & Indicators | AW1: References to legislation
A2: Policy Instrument ID | B2: Instrument / subscheme | C2: Group | D2: Approach | E2: Emission sector | F2: Sub-sector | G2: Domestic instrument name | H2: English instrument name | I2: Policy Package | J2: Description | K2: Objective | L2: Mitigation relevance | M2: Jurisdiction level | N2: Jurisdiction name | O2: Adoption date | P2: Start date | Q2: End date | R2: Last revisions | S2: Last revisions (Details) | T2: Status | U2: Administrating authorities | V2: Asset | W2: Asset (Status) | X2: Asset (Details) | Y2: Asset (Other) | Z2: Asset (Cut-off range) | AA2: Agent | AB2: Agent (Detail) | AC2: Activity | AD2: Activity (Details) | AE2: Intensity (Value) | AF2: Intensity (Unit) | AG2: Intensity (Details) | AH2: Requirement specification | AI2: Compliance calculation methodology I | AJ2: Compliance calculation methodology II | AK2: Compliance monitoring | AL2: Compliance monitoring details | AM2: Compliance enforcement | AN2: Compliance enforcement details | AO2: Compliance promotion | AP2: Compliance promotion detail | AQ2: GHG emission coverage (absolute) | AR2: GHG emission coverage (% domestic emissions) | AS2: Economic sector | AT2: GHGs affected | AU2: Mitigation effects | AV2: Mitigation co-benefits | AW2: Legal statute | AX2: Legal document | AY2: Other weblinks

Sheet Government I&C
A1: Identification | C1: Instrument typology | G1: Policy Description | M1: Administrative information | V1: Policy regulatory base and intensity | AK1: Instrument-specific attributes | AS1: GHG emission base | AU1: Classifications & Indicators | AY1: References to legislation
A2: Policy Instrument ID | B2: Instrument / subscheme | C2: Group | D2: Approach | E2: Emission sector | F2: Sub-sector | G2: Domestic instrument name | H2: English instrument name | I2: Policy Package | J2: Description | K2: Objective | L2: Mitigation relevance | M2: Jurisdiction level | N2: Jurisdiction name | O2: Adoption date | P2: Start date | Q2: End date | R2: Last revisions | S2: Last revisions (Details) | T2: Status | U2: Administrating authorities | V2: Asset | W2: Asset (Status) | X2: Asset (Details) | Y2: Asset (Other) | Z2: Asset (Cut-off range) | AA2: Agent | AB2: Agent (Detail) | AC2: Activity | AD2: Activity (Details) | AE2: Intensity (Value) | AF2: Intensity (Unit) | AG2: Intensity (Details) | AH2: Requirement specification | AI2: Compliance calculation methodology I | AJ2: Compliance calculation methodology II | AK2: Public investment: Co-financing | AL2: Public investment: Selection process | AM2: Public procurement: Tender process | AN2: Public procurement: Award criteria tender process | AO2: Public procurement: Compliance monitoring | AP2: Public procurement: Compliance enforcement | AQ2: Public procurement: Life-cycle costing | AR2: Public investment/procurement: Annual expenditure | AS2: GHG emission coverage (absolute) | AT2: GHG emission coverage (% domestic emissions) | AU2: Economic sector | AV2: GHGs affected | AW2: Mitigation effect | AX2: Mitigation co-benefits | AY2: Legal statute | AZ2: Legal document | BA2: Other weblinks

Sheet Information instruments
A1: Identification | C1: Instrument typology | G1: Policy description | M1: Administrative information | V1: Policy regulatory base and intensity | AK1: Instrument-specific attributes | AU1: GHG emission base | AW1: Classifications & Indicators | BA1: References to legislation
A2: Policy Instrument ID | B2: Instrument / subscheme | C2: Group | D2: Approach | E2: Emission sector | F2: Sub-sector | G2: Domestic instrument name | H2: English instrument name | I2: Policy Package | J2: Description | K2: Objective | L2: Mitigation relevance | M2: Jurisdiction level | N2: Jurisdiction name | O2: Adoption date | P2: Start date | Q2: End date | R2: Last revision | S2: Last revision (Details) | T2: Status | U2: Administrating authorities | V2: Asset | W2: Asset (Status) | X2: Asset (Details) | Y2: Asset (Other) | Z2: Asset (Cut-off range) | AA2: Agent | AB2: Agent (Detail) | AC2: Activity | AD2: Activity (Details) | AE2: Intensity (Value) | AF2: Intensity (Unit) | AG2: Intensity (Details) | AH2: Requirement specification | AI2: Compliance calculation methodology I | AJ2: Compliance calculation methodology II | AK2: Instrument linkage | AL2: Responsibility information capturing | AM2: Information transmission | AN2: Frequency of information provision | AO2: Public availability of information | AP2: For labels: Type | AQ2: Compliance monitoring | AR2: Compliance enforcement | AS2: Compliance promotion | AT2: Details on capacity building, training/education, information campaigns and award schemes | AU2: GHG emission coverage (absolute) | AV2: GHG emission coverage (% domestic emissions) | AW2: Economic sector | AX2: GHGs affected | AY2: Mitigation effect | AZ2: Mitigation co-benefits | BA2: Legal statute | BB2: Legal document | BC2: Other weblinks

Sheet Cover
A1: China Climate Policy Instrument Database (CCPID)
A3: developed by MGF Lab, National School of Development, Peking University
A4: as of September 2026
A6: Overview
A7: This database provides a comprehensive overview of China's national-level climate change mitigation and mitigation-relevant policy instruments currently in force. It is structured to align with the typology and data framework of the OECD's IFCMA Climate Policy Database, incorportating necessary adjustments to reflect the characteristics of China's policy instruments and to faciliate further analysis. Adjustments to the typology of the IFCMA Climate Policy Database 1. Economic instruments: one new instrument group has been included: - Administered price. Adjustments to the data structure of the IFCMA Climate Policy Database Two new attributes have been added: - "Sub-sector" added in the "Instrument typology" block; - "Mitigation relevance" added in the "Policy description" block.
A10: Content of this file
A11: Spreadsheet | D11: Description
A12: Cover | D12: Introduces this document, presents its overall function and lists MGF Lab contact points
A13: Classification framework | D13: Explains the four-level classification framework of this dataset
A14: Categories and groups | D14: Demonstrates instrument categories and instrument groups within each category
A15: Summary | D15: Provides information on the number of policy instruments collected to date, by instrument category, group, approach, and sector covered
A16: Approaches | D16: Demonstrates instrument approaches within each group, and provides definition for each of them
A17: Instruments overview | D17: Provides a simplified summary table of all policy instruments collected to date
A18: Economic instruments | D18: Displays information for the Economic Instruments
A19: Regulatory instruments | D19: Displays information for the Regulatory Instruments
A20: Government I&C | D20: Displays information for the Government Investment & Consumption Instruments
A21: Information instruments | D21: Displays information for the Information Instruments
A22: Voluntary approaches | D22: Displays information for the Voluntary Approaches
... A24: Ended | D24: Displays information for policy instruments that were once included in this database but have since expired or been terminated
A26: Legend
A27: Bold text | D27: Policy instrument
A28: Unbolded text | D28: Sub-schemes of the policy instrument
A31: MGF Lab contact
A32: Danqing Shao | B32: dqshao@nsd.pku.edu.cn
A33: Xiaobei He | B33: xbhe@nsd.pku.edu.cn

Sheet Voluntary approaches
A1: Identification | C1: Instrument typology | G1: Policy Description | M1: Administrative information | V1: Policy regulatory base and intensity | AK1: Instrument-specific attributes | AN1: GHG emission base | AP1: Classifications & Indicators | AT1: References to legislation
A2: Policy Instrument ID | B2: Instrument / subscheme | C2: Group | D2: Approach | E2: Emission sector | F2: Sub-sector | G2: Domestic instrument name | H2: English instrument name | I2: Policy Package | J2: Description | K2: Objective | L2: Mitigation relevance | M2: Jurisdiction level | N2: Jurisdiction name | O2: Adoption date | P2: Start date | Q2: End date | R2: Last revisions | S2: Last revisions (Details) | T2: Status | U2: Administrating authorities | V2: Asset | W2: Asset (Status) | X2: Asset (Details) | Y2: Asset (Other) | Z2: Asset (Cut-off range) | AA2: Agent | AB2: Agent (Detail) | AC2: Activity | AD2: Activity (Details) | AE2: Intensity (Value) | AF2: Intensity (Unit) | AG2: Intensity (Details) | AH2: Requirement specification | AI2: Compliance calculation methodology I | AJ2: Compliance calculation methodology II | AK2: Incentives for Participation | AL2: Monitoring | AM2: Sanctions for non-compliance | AN2: GHG emission coverage (absolute) | AO2: GHG emission coverage (% domestic emissions) | AP2: Economic sector | AQ2: GHGs affected | AR2: Mitigation effect | AS2: Mitigation co-benefits | AT2: Legal statute | AU2: Legal document | AV2: Other weblinks

Sheet Classification framework
A1: This dataset adopts a four-level classification framework aligned with the IFCMA Climate Policy Database. The classification distinguishes between standardised, internationally comparable policy approaches and country-specific policy instruments, while allowing for additional granularity where needed.
A3: Classification Structure
A4: Level | B4: Name | C4: Chinese Name | D4: Definition | E4: Purpose in Dataset | F4: Example
A5: 1 | B5: Category | C5: 类别 | D5: High-level classification based on the policy instrument’s operating mechanism | E5: Provides overall structure and enables broad comparison across policy types | F5: Economic instruments; Regulatory instruments; Information instruments
A6: 2 | B6: Group | C6: 组别 | D6: Functional grouping of instruments within each category | E6: Organises instruments by regulatory function or policy logic | F6: Under regulatory instruments: Performance standards; Technology standards
A7: 3 | B7: Approach | C7: 路径 | D7: A standardised and internationally comparable policy approach that groups instruments with similar design and regulatory logic | E7: Core level for cross-country comparability | F7: Under performance standards: Minimum Energy Performance Standards (MEPS) for electric appliances; Fuel economy standards
A8: 4 | B8: Instrument | C8: 工具 | D8: A specific legal or regulatory measure implemented in a jurisdiction at a given time | E8: Primary unit of observation in the dataset; reflects country-specific policy design | F8: Under MEPS for electric appliances: MEPS for power transformer; MEPS for monitor; MEPS for air purifier
B9: Sub-scheme (optional) | C9: 子方案（可选） | D9: Variations within a single instrument reflecting differentiated requirements, exemptions, or implementation phases | E9: Captures within-instrument heterogeneity when relevant | F9: Efficiency tiers (e.g. Grade 1 / Grade 2); Phase-in periods
A11: Counting Rules
A12: Approach level | B12: Counted once for comparability
A13: Instrument level | B13: Counted separately for each policy
A14: Sub-scheme level | B14: Not counted as independent instruments

Sheet Categories and groups
A1: Category | B1: Operating Mechanism | C1: Group | D1: Definition
A2: Economic instruments | B2: Incentivise | C2: Subsidy | D2: Unrequited payments from government to non-government units
C3: Tax | D3: Compulsory unrequited payments to a government unit
C4: Trading scheme | D4: Trading schemes cause changes in the relative costs or prices faced by economic agents by regulating the trade of permits or certificates, which may cause a direct financial benefit (e.g. by providing the options of selling them) or set a price on the behaviour of the regulated agents (e.g. by providing the options of purchasing them).
C5: Administered price | D5: Government-administered pricing mechanisms that directly set, differentiate, or regulate prices of energy or emissions-intensive activities to influence behaviour, without operating through explicit fiscal transfers or tax instruments.
A6: Regulatory instruments | B6: Mandate | C6: Performance standard | D6: Performance standards mandate a specific outcome, giving regulated agents the freedom to choose technologies and processes to achieve the specified performance level.
C7: Technology standard | D7: Technology standards require or prohibit a specific input or technology, or design for production.
C8: Framework regulation | D8: Framework standards prescribe requirements on production processes without mandating the use of specific inputs or technologies or prescribing a specific outcome. Often, these requirements are of qualitative nature and they may require case-by-case interpretation and application. They may also regulate the functioning of markets.
A9: Government investment and consumption | B9: Enable and guide | C9: Public investment | D9: Spending by a government unit towards forming fixed capital such as transport and energy infrastructure, or nature-based infrastructure solutions, as well as intangible assets such as R&D.
C10: Public procuremet | D10: Instruments that oblige or encourage public agents to consider climate change mitigation impacts when purchasing the goods, services and works from external suppliers or providers to fulfil public sector needs, deliver public services, and execute government projects and programmes.
C11: Public appraisal rule | D11: Public appraisal rules prescribe requirements on the decision-making processes and operations of the government without mandating the use of specific inputs or technologies or prescribing a specific outcome. Rather, they specify the process to be followed in decision-making processes and operations or define qualitative outcomes that may require case-by-case interpretation.
A12: Information instruments | B12: Enable and guide | C12: Comparative energy efficiency label | D12: A mandatory label that provides standardised, comparable information on the energy efficiency of products, buildings, or vehicles to guide consumer decision-making.
C13: Reporting requirement | D13: Reporting requirements mandate agents to submit regular reports, disclosures, or documentation to the regulating agents, oversight bodies, or stakeholders.
C14: Capacity building and public awareness | D14: Government provides information to non-government units to disseminate information, raise awareness, and enhance understanding on specific issues, initiatives, or policies.
A15: Voluntary approaches | B15: Enable and guide | C15: Voluntary information instrument | D15: Voluntary information instruments are established by governments to facilitate private action towards climate objectives. Participation is voluntary. Firms can choose to adopt to inform stakeholders and consumers about their environmental performance. Examples: voluntary energy efficiency labels; voluntary financial labels, voluntary reporting standards; voluntary audits.
C16: Voluntary trading system | D16: Voluntary trading systems are established by government to allow organisations or companies to trade credits or allowances representing emissions reductions or other environmental benefits. Participation is voluntary, and these systems often operate parallel to or in the absence of mandatory trading systems. Examples: voluntary GHG emission trading systems.
C17: Voluntary target | D17: Specific self-imposed goals set by organisations or companies to achieve climate objectives or improve environmental performance beyond regulatory compliance in collaboration with the government. Examples: voluntary GHG emission reduction targets, voluntary energy performance targets.
A19: Source: IFCMA(2024), MGF Lab.

Sheet Attributes definitions
A1: Block | B1: Attribute | C1: Attribute definition | D1: Entry Type | E1: Details
A2: Common Attributes
A3: Identification | B3: Instrument / subscheme | C3: Indicates whether the entry (the row in the Excel sheet) is the policy instrument or a sub-scheme (i.e. a variation of the policy instrument) | D3: Categorial | E3: Instrument; Subscheme
A4: Instrument typology | B4: Instrument type | C4: Instrument type according to IFCMA typology (cf IFCMA(2024)4/REV1) | D4: Categorial | E4: E.g., Taxes, Subsidies; Technology standards; Performance standards, …
B5: Instrument name | C5: Preliminary IFCMA harmonised instrument name (instrument list is under development) | D5: Categorial | E5: E.g., Carbon tax, Renewable electricity feed-in tariff, Subsidy for CCS, Bans and phase outs of ICE vehicles, Fuel Economy Standards, …
B6: Emission sector | C6: Preliminary IFCMA classification based on IPCC emission source sector classification, simplified version | D6: Categorial | E6: Energy, transport, buildings, industry, agriculture, waste, LULUCF
B7: Sub-sector | C7: Specify the sub-sector(s) under the "Emission sector" ; otherwise, use the same designation as the "Emission sector". | D7: Categorial | E7: Coal, solar power, wind power, hydrogen, nuclear power, steel, cement, automobile, battery, etc.
A8: General information | B8: Domestic name | C8: Instrument name in original language. Preferably the name the policy is commonly known for. If there is ambiguity about the instrument name, the name used in the instrument's legal statute(s) | D8: Free text | E8: N/A
B9: English name | C9: English translation of domestic instrument name | D9: Free text | E9: N/A
B10: Policy package name | C10: The name of the policy package, if applicable. A policy package refers to an overarching framework that deliberately bundles and implements multiple instruments together to achieve synergistic effects, maximise overall impact, or minimise potential trade-offs. Examples include broad legislative packages such as building codes, or frameworks such as the United States 2022 Inflation Reduction Act or the European Union’s Fit for 55 legislation. It excludes “horizontal” linkages between policies, such as earmarking tax revenue for specific subsidies; these linkages are captured through the instrument-specific attributes | D10: Free | E10: N/A
B11: Description | C11: Brief description of the policy mechanism and specific design features | D11: Free | E11: N/A
B12: Objective | C12: Policy objective as explicitly stated in the legislation | D12: Categorial (multiple choice) | E12: Climate change mitigation; Non-fossil energy; Energy efficiency; Green economy; Technological innovation; Energy security; Pollution control; Ecological protection; Circular economy; Adaptation; Green finance; Electrification; Industrial development; Green consumption; Information disclosure; Public awareness; Ozone layer protection
B13: Mitigation relevance | C13: Indicates whether the policy instrument is a climate change mitigation one or a mitigation-relevant one. Direct means it is a mitigation instrument which explicitly intends to reduce or remove GHG emissions. Indirect means it is a mitigation-relevant instrument which may induce changes in emissions (positive or negative) without necessarily having emission reductions or removals as a primary goal. | D13: Categorial | E13: Direct; Indirect
B14: Jurisdiction level | C14: Jurisdiction level where the instrument is applied | D14: Categorial (single choice) | E14: National; Sub-national; Supra-national; Special economic zone
B15: Jurisdiction name | C15: Name of jurisdiction if it is applied at supra- / international or subnational level in english language | D15: Free | E15: N/A
B16: Status | C16: Defines if the instrument is active or inactive, and whether it is in force | D16: Categorial (single choice) | E16: In force; Scheduled; Ended; Non-existent
B17: Adoption date | C17: Date when the instrument is approved | D17: DMY protocol | E17: Fixed structure [mm/yyyy] or [yyyy]
B18: Start date | C18: Date of entry into force/ when the instrument became or will become legally binding | D18: DMY protocol | E18: Fixed structure [mm/yyyy] or [yyyy]
B19: End date | C19: Date when the final requirement of the legal mandate takes effect, if relevant | D19: DMY protocol | E19: Fixed structure [mm/yyyy] or [yyyy]
B20: Last revision | C20: Date of the last update/revision to the policy instrument | D20: DMY protocol | E20: Fixed structure [mm/yyyy] or [yyyy]
B21: Last revision details | C21: Informs on the nature of the last revision if applicable, what has been modified [broader scope, different intensity, new earmarking, etc) and/or previous relevant revisions | D21: Free text
B22: Aministrating authority | C22: The institution(s) that implement and manage the instrument. This involves setting rates and/or defining the policy base | D22: Free | E22: N/A
A23: Policy regulatory base and intensity | B23: Regulated asset | C23: The object that is regulated; this can be a structure (e.g. boilers and turbines), a fuel (e.g. coal or gas), emissions, more generic objects such as products and inputs, as well as intangible assets | D23: Categorial (multiple choice), free for details | E23: Non-exhaustive list
B24: Regulated asset (Status) | C24: Asset status, i.e. whether an asset is newly sold or build, already existing (building stock or vehicle fleet) or is sold used | D24: Categorial | E24: New; existing
B25: Regulated asset (Details) | C25: Asset type, which can take various forms depending on asset. Could include enginge types, or other technological specifications | D25: Categorial | E25: Non-exhaustive list
B26: Regulated asset (Other) | C26: Other details relevant to define the regulated assets | D26: Free | E26: N/A
B27: Regulated asset (Cut-off range) | C27: Refers to the specific details outlining the range or category of the regulatory base that is subject to the regulation by the instrument. The brackets delineate the boundaries within which regulatory stipulations are applied by the instrument. It could be income brackets, asset classes (e.g. based on size). | D27: Open structure | E27: [XXXX ; YYYY] + unit
B28: Regulated agent | C28: Entity that must legally comply with the policy instrument, or that receive the established benefit or information | D28: Categorial (multiple choice), free for details | E28: Households; Firms; Governments; Non-governmental organisations
B29: Regulated agent (Detail) | C29: Details relevant to define the regulated agents (e.g., vehicles older than 10 years, housholds/firms above a certain revenue treshhold, etc.) | D29: Free | E29: N/A
B30: Regulated activity | C30: The point of incidence when the policy instrument intervenes | D30: Categorial (multiple choice), free for details | E30: Non-exhaustive list
B31: Regulated activity (Details) | C31: Other details relevant to define the regulated activity | D31: Free | E31: N/A
B32: Intensity (Value) | C32: The numerical value used in the legislation (level, rate, target, etc) | D32: Free | E32: N/A
B33: Intensity (Unit) | C33: The unit of the intensity value, e.g. EUR, km, %, level, etc. | D33: Free | E33: [unit as stated in the regulation]
B34: Intensity (Details) | C34: Further details about the intensity, if necessary, e.g. if the intensity is calculated on a formula, the formula and an average intensity value can be provided | D34: Free | E34: N/A
B35: Requirement specification | C35: If an intensity changes based on a requirement not yet captured in the asset, activity or agent attributes but is relevant to understand and describe a policy instrument, this requirement is entered here. | D35: Free | E35: N/A
... B37: Compliance calculation methodology II | C37: Describes the methodology or rules used to evaluate compliance with the instrument’s requirements. | D37: Free | E37: N/A
A38: References to legislation | B38: Legal statute | C38: Name of relevant legal document(s) and chapter(s) and/or article(s) that established or modified the instrument (if revised) | D38: Free | E38: N/A
B39: Legal document | C39: Weblink to the relevant legal document that established or modified the instrument (if revised) | D39: Free | E39: N/A
B40: Other relevant websites | C40: Weblinks to other relevant websites | D40: Free | E40: N/A
A41: GHG emission base | B41: GHG emission coverage (absolute) | C41: Quantification of the instrument's emission base, in absolute terms | D41: Numerical | E41: in KtCO2eq
...

Sheet Ended
A1: English name | B1: Domestic instrument name | C1: Status | D1: Start year | E1: End year | F1: Instrument category | G1: Instrument group | H1: Emission sector | I1: Sub-sector | J1: Legal document | K1: Weblinks
A2: Electric vehicle purchase subsidy | B2: 新能源汽车推广应用补贴 | C2: Ended | D2: 2009 | E2: 2022 | F2: Economic | G2: Subsidy | H2: Transport | I2: Vehicle | J2: http://www.mof.gov.cn/gkml/caizhengwengao/2009niancaizhengbuwengao/caizhengwengao2009dierqi/200904/t20090413_132178.htm | K2: https://www.gov.cn/zhengce/zhengceku/2021-12/31/content_5665857.htm
A3: Subsidy for the Construction of Electric Vehicle Charging Infrastructure | B3: 电动汽车充电基础设施建设奖补 | C3: Ended | D3: 2015 | E3: 2020 | F3: Economic | G3: Subsidy | H3: Transport | I3: Vehicle | J3: http://www.mof.gov.cn/gp/xxgkml/jjjss/201601/t20160120_2512185.htm | K3: https://www.gov.cn/zhengce/content/2015-10/09/content_10214.htm
A4: Renewable electricity feed-in tariff | B4: 可再生能源上网电价补贴 | C4: Ended | D4: 2006 | E4: 2021 | F4: Economic | G4: Subsidy | H4: Energy | I4: Solar power; wind power | J4: https://www.ndrc.gov.cn/xxgk/zcfb/tz/200601/t20060120_965897.html | K4: https://zfxxgk.ndrc.gov.cn/web/iteminfo.jsp?id=19761
A5: Value-added tax incentive | B5: 风力发电增值税优惠 | C5: Ended | D5: 2015 | E5: 2025 | F5: Economic | G5: Tax | H5: Energy | I5: Wind power | J5: http://www.mof.gov.cn/gkml/caizhengwengao/wg2015/wg201508/201601/t20160107_1645704.htm | K5: https://shanghai.chinatax.gov.cn/zcfw/zcfgk/zzs/201507/t417892.html
A6: Value-added tax incentive | B6: 核电增值税优惠 | C6: Ended | D6: 2008 | E6: 2025 | F6: Economic | G6: Tax | H6: Energy | I6: Nuclear power | J6: http://www.mof.gov.cn/zhengwuxinxi/caizhengxinwen/200805/t20080519_29110.htm | K6: https://guizhou.chinatax.gov.cn/wjjb/zcfgk/szfl/ygsf/202203/t20220310_72917823.html
A7: Vehicle purchase subsidy (fuel cell vehicle) | B7: 燃料电池汽车示范应用奖补 | C7: Ended | D7: 2021 | E7: 2025 | F7: Economic | G7: Subsidy | H7: Transport | I7: Vehicle | J7: https://www.gov.cn/zhengce/zhengceku/2020-09/21/content_5545221.htm | K7: http://jjs.mof.gov.cn/zhengcefagui/202009/t20200918_3591168.htm
A8: Central bank targeted relending for the clean and efficient use of coal | B8: 支持煤炭清洁高效利用专项再贷款 | C8: Ended | D8: 2021 | E8: 2023 | F8: Economic | G8: Subsidy | H8: Energy | I8: Coal | J8: https://kj.jdz.gov.cn/zwzx/ztzl/kjjr/zc/t1036092.shtml | K8: https://www.gov.cn/zhengce/2021-11/18/content_5651619.htm
